//לצורך ניהול שגיאות ומניעת חזרה על קוד- כאשר חוזרת שגיאה מפונקציה אסינכרונית נעצור את הריצה וננתב 
//  לניהול השגיאות - NEXT
//נבנה פונקציה עוטפת- שתקבל פונקציה בתור משתנה ורק במקרה והפונקציה הפנימית נכשלת ננהל את השגיאה
module.exports = func => {
    return (req, res, next) => {
        func(req, res, next).catch(next);
    }
}